INFO:werkzeug:192.168.5.2 - - [25/Aug/2022 11:43:31] "GET / HTTP/1.1" 200 -
ERROR:Zortom:Exception on /cdn/0.3497161147862804 [GET]
Traceback (most recent call last):
  File "/home/c/Code/VConf310/lib/python3.10/site-packages/flask/app.py", line 2525, in wsgi_app
    response = self.full_dispatch_request()
  File "/home/c/Code/VConf310/lib/python3.10/site-packages/flask/app.py", line 1822, in full_dispatch_request
    rv = self.handle_user_exception(e)
  File "/home/c/Code/VConf310/lib/python3.10/site-packages/flask/app.py", line 1820, in full_dispatch_request
    rv = self.dispatch_request()
  File "/home/c/Code/VConf310/lib/python3.10/site-packages/flask/app.py", line 1796, in dispatch_request
    return self.ensure_sync(self.view_functions[rule.endpoint])(**view_args)
  File "/home/c/Code/github/tFlask-Image-Gallery/routes.py", line 42, in download_file
    if Path(app.instance_path, 'qrs', filename).exists():
  File "/usr/lib/python3.10/pathlib.py", line 958, in __new__
    self = cls._from_parts(args)
  File "/usr/lib/python3.10/pathlib.py", line 592, in _from_parts
    drv, root, parts = self._parse_args(args)
  File "/usr/lib/python3.10/pathlib.py", line 576, in _parse_args
    a = os.fspath(a)
TypeError: expected str, bytes or os.PathLike object, not NoneType
INFO:werkzeug:192.168.5.2 - - [25/Aug/2022 11:43:31] "[35m[1mGET /cdn/0.3497161147862804 HTTP/1.1[0m" 500 -
INFO:werkzeug:192.168.5.2 - - [25/Aug/2022 11:49:05] "GET / HTTP/1.1" 200 -
ERROR:Zortom:Exception on /cdn/0.3497161147862804 [GET]
Traceback (most recent call last):
  File "/home/c/Code/VConf310/lib/python3.10/site-packages/flask/app.py", line 2525, in wsgi_app
    response = self.full_dispatch_request()
  File "/home/c/Code/VConf310/lib/python3.10/site-packages/flask/app.py", line 1822, in full_dispatch_request
    rv = self.handle_user_exception(e)
  File "/home/c/Code/VConf310/lib/python3.10/site-packages/flask/app.py", line 1820, in full_dispatch_request
    rv = self.dispatch_request()
  File "/home/c/Code/VConf310/lib/python3.10/site-packages/flask/app.py", line 1796, in dispatch_request
    return self.ensure_sync(self.view_functions[rule.endpoint])(**view_args)
  File "/home/c/Code/github/tFlask-Image-Gallery/routes.py", line 42, in download_file
    if Path(app.instance_path, 'qrs', filename).exists():
  File "/usr/lib/python3.10/pathlib.py", line 958, in __new__
    self = cls._from_parts(args)
  File "/usr/lib/python3.10/pathlib.py", line 592, in _from_parts
    drv, root, parts = self._parse_args(args)
  File "/usr/lib/python3.10/pathlib.py", line 576, in _parse_args
    a = os.fspath(a)
TypeError: expected str, bytes or os.PathLike object, not NoneType
INFO:werkzeug:192.168.5.2 - - [25/Aug/2022 11:49:05] "[35m[1mGET /cdn/0.3497161147862804 HTTP/1.1[0m" 500 -
INFO:werkzeug:192.168.5.2 - - [25/Aug/2022 11:53:55] "GET / HTTP/1.1" 200 -
INFO:werkzeug:192.168.5.2 - - [25/Aug/2022 11:59:22] "GET /cdn/0.9723143878602916 HTTP/1.1" 200 -
INFO:werkzeug:192.168.5.2 - - [25/Aug/2022 12:00:08] "GET /cdn/0.9723143878602916 HTTP/1.1" 200 -
INFO:werkzeug:192.168.5.2 - - [25/Aug/2022 12:29:08] "[36mGET /static/style.css HTTP/1.1[0m" 304 -
INFO:werkzeug:192.168.5.2 - - [25/Aug/2022 12:29:08] "[36mGET /static/script.js HTTP/1.1[0m" 304 -
INFO:werkzeug:192.168.5.2 - - [25/Aug/2022 12:29:08] "[33mGET /blah HTTP/1.1[0m" 404 -
ERROR:Zortom:Exception on /cdn/0.10968879725419711 [GET]
Traceback (most recent call last):
  File "/home/c/Code/VConf310/lib/python3.10/site-packages/flask/app.py", line 2525, in wsgi_app
    response = self.full_dispatch_request()
  File "/home/c/Code/VConf310/lib/python3.10/site-packages/flask/app.py", line 1822, in full_dispatch_request
    rv = self.handle_user_exception(e)
  File "/home/c/Code/VConf310/lib/python3.10/site-packages/flask/app.py", line 1820, in full_dispatch_request
    rv = self.dispatch_request()
  File "/home/c/Code/VConf310/lib/python3.10/site-packages/flask/app.py", line 1796, in dispatch_request
    return self.ensure_sync(self.view_functions[rule.endpoint])(**view_args)
  File "/home/c/Code/github/tFlask-Image-Gallery/routes.py", line 42, in download_file
    if Path(app.instance_path, 'qrs', filename).exists():
UnboundLocalError: local variable 'filename' referenced before assignment
INFO:werkzeug:192.168.5.2 - - [25/Aug/2022 12:29:08] "[35m[1mGET /cdn/0.10968879725419711 HTTP/1.1[0m" 500 -
ERROR:Zortom:Exception on /cdn/0.15221885623000042 [GET]
Traceback (most recent call last):
  File "/home/c/Code/VConf310/lib/python3.10/site-packages/flask/app.py", line 2525, in wsgi_app
    response = self.full_dispatch_request()
  File "/home/c/Code/VConf310/lib/python3.10/site-packages/flask/app.py", line 1822, in full_dispatch_request
    rv = self.handle_user_exception(e)
  File "/home/c/Code/VConf310/lib/python3.10/site-packages/flask/app.py", line 1820, in full_dispatch_request
    rv = self.dispatch_request()
  File "/home/c/Code/VConf310/lib/python3.10/site-packages/flask/app.py", line 1796, in dispatch_request
    return self.ensure_sync(self.view_functions[rule.endpoint])(**view_args)
  File "/home/c/Code/github/tFlask-Image-Gallery/routes.py", line 42, in download_file
    if Path(app.instance_path, 'qrs', filename).exists():
UnboundLocalError: local variable 'filename' referenced before assignment
INFO:werkzeug:192.168.5.2 - - [25/Aug/2022 12:29:08] "[35m[1mGET /cdn/0.15221885623000042 HTTP/1.1[0m" 500 -
ERROR:Zortom:Exception on /cdn/0.2733754010067362 [GET]
Traceback (most recent call last):
  File "/home/c/Code/VConf310/lib/python3.10/site-packages/flask/app.py", line 2525, in wsgi_app
    response = self.full_dispatch_request()
  File "/home/c/Code/VConf310/lib/python3.10/site-packages/flask/app.py", line 1822, in full_dispatch_request
    rv = self.handle_user_exception(e)
  File "/home/c/Code/VConf310/lib/python3.10/site-packages/flask/app.py", line 1820, in full_dispatch_request
    rv = self.dispatch_request()
  File "/home/c/Code/VConf310/lib/python3.10/site-packages/flask/app.py", line 1796, in dispatch_request
    return self.ensure_sync(self.view_functions[rule.endpoint])(**view_args)
  File "/home/c/Code/github/tFlask-Image-Gallery/routes.py", line 42, in download_file
    if Path(app.instance_path, 'qrs', filename).exists():
UnboundLocalError: local variable 'filename' referenced before assignment
ERROR:Zortom:Exception on /cdn/0.0721805612601566 [GET]
Traceback (most recent call last):
  File "/home/c/Code/VConf310/lib/python3.10/site-packages/flask/app.py", line 2525, in wsgi_app
    response = self.full_dispatch_request()
  File "/home/c/Code/VConf310/lib/python3.10/site-packages/flask/app.py", line 1822, in full_dispatch_request
    rv = self.handle_user_exception(e)
  File "/home/c/Code/VConf310/lib/python3.10/site-packages/flask/app.py", line 1820, in full_dispatch_request
    rv = self.dispatch_request()
  File "/home/c/Code/VConf310/lib/python3.10/site-packages/flask/app.py", line 1796, in dispatch_request
    return self.ensure_sync(self.view_functions[rule.endpoint])(**view_args)
  File "/home/c/Code/github/tFlask-Image-Gallery/routes.py", line 42, in download_file
    if Path(app.instance_path, 'qrs', filename).exists():
UnboundLocalError: local variable 'filename' referenced before assignment
ERROR:Zortom:Exception on /cdn/0.24851529299525577 [GET]
Traceback (most recent call last):
  File "/home/c/Code/VConf310/lib/python3.10/site-packages/flask/app.py", line 2525, in wsgi_app
    response = self.full_dispatch_request()
  File "/home/c/Code/VConf310/lib/python3.10/site-packages/flask/app.py", line 1822, in full_dispatch_request
    rv = self.handle_user_exception(e)
  File "/home/c/Code/VConf310/lib/python3.10/site-packages/flask/app.py", line 1820, in full_dispatch_request
    rv = self.dispatch_request()
  File "/home/c/Code/VConf310/lib/python3.10/site-packages/flask/app.py", line 1796, in dispatch_request
    return self.ensure_sync(self.view_functions[rule.endpoint])(**view_args)
  File "/home/c/Code/github/tFlask-Image-Gallery/routes.py", line 42, in download_file
    if Path(app.instance_path, 'qrs', filename).exists():
UnboundLocalError: local variable 'filename' referenced before assignment
ERROR:Zortom:Exception on /cdn/0.32402690003715784 [GET]
Traceback (most recent call last):
  File "/home/c/Code/VConf310/lib/python3.10/site-packages/flask/app.py", line 2525, in wsgi_app
    response = self.full_dispatch_request()
  File "/home/c/Code/VConf310/lib/python3.10/site-packages/flask/app.py", line 1822, in full_dispatch_request
    rv = self.handle_user_exception(e)
  File "/home/c/Code/VConf310/lib/python3.10/site-packages/flask/app.py", line 1820, in full_dispatch_request
    rv = self.dispatch_request()
  File "/home/c/Code/VConf310/lib/python3.10/site-packages/flask/app.py", line 1796, in dispatch_request
    return self.ensure_sync(self.view_functions[rule.endpoint])(**view_args)
  File "/home/c/Code/github/tFlask-Image-Gallery/routes.py", line 42, in download_file
    if Path(app.instance_path, 'qrs', filename).exists():
UnboundLocalError: local variable 'filename' referenced before assignment
INFO:werkzeug:192.168.5.2 - - [25/Aug/2022 12:29:08] "[35m[1mGET /cdn/0.2733754010067362 HTTP/1.1[0m" 500 -
INFO:werkzeug:192.168.5.2 - - [25/Aug/2022 12:29:08] "[35m[1mGET /cdn/0.0721805612601566 HTTP/1.1[0m" 500 -
INFO:werkzeug:192.168.5.2 - - [25/Aug/2022 12:29:08] "[35m[1mGET /cdn/0.24851529299525577 HTTP/1.1[0m" 500 -
INFO:werkzeug:192.168.5.2 - - [25/Aug/2022 12:29:08] "[35m[1mGET /cdn/0.32402690003715784 HTTP/1.1[0m" 500 -
ERROR:Zortom:Exception on /cdn/0.37156060928832113 [GET]
Traceback (most recent call last):
  File "/home/c/Code/VConf310/lib/python3.10/site-packages/flask/app.py", line 2525, in wsgi_app
    response = self.full_dispatch_request()
  File "/home/c/Code/VConf310/lib/python3.10/site-packages/flask/app.py", line 1822, in full_dispatch_request
    rv = self.handle_user_exception(e)
  File "/home/c/Code/VConf310/lib/python3.10/site-packages/flask/app.py", line 1820, in full_dispatch_request
    rv = self.dispatch_request()
  File "/home/c/Code/VConf310/lib/python3.10/site-packages/flask/app.py", line 1796, in dispatch_request
    return self.ensure_sync(self.view_functions[rule.endpoint])(**view_args)
  File "/home/c/Code/github/tFlask-Image-Gallery/routes.py", line 42, in download_file
    if Path(app.instance_path, 'qrs', filename).exists():
UnboundLocalError: local variable 'filename' referenced before assignment
INFO:werkzeug:192.168.5.2 - - [25/Aug/2022 12:29:08] "[35m[1mGET /cdn/0.37156060928832113 HTTP/1.1[0m" 500 -
ERROR:Zortom:Exception on /cdn/0.4564846952232354 [GET]
Traceback (most recent call last):
  File "/home/c/Code/VConf310/lib/python3.10/site-packages/flask/app.py", line 2525, in wsgi_app
    response = self.full_dispatch_request()
  File "/home/c/Code/VConf310/lib/python3.10/site-packages/flask/app.py", line 1822, in full_dispatch_request
    rv = self.handle_user_exception(e)
  File "/home/c/Code/VConf310/lib/python3.10/site-packages/flask/app.py", line 1820, in full_dispatch_request
    rv = self.dispatch_request()
  File "/home/c/Code/VConf310/lib/python3.10/site-packages/flask/app.py", line 1796, in dispatch_request
    return self.ensure_sync(self.view_functions[rule.endpoint])(**view_args)
  File "/home/c/Code/github/tFlask-Image-Gallery/routes.py", line 42, in download_file
    if Path(app.instance_path, 'qrs', filename).exists():
UnboundLocalError: local variable 'filename' referenced before assignment
ERROR:Zortom:Exception on /cdn/0.5113559359673016 [GET]
Traceback (most recent call last):
  File "/home/c/Code/VConf310/lib/python3.10/site-packages/flask/app.py", line 2525, in wsgi_app
    response = self.full_dispatch_request()
  File "/home/c/Code/VConf310/lib/python3.10/site-packages/flask/app.py", line 1822, in full_dispatch_request
    rv = self.handle_user_exception(e)
  File "/home/c/Code/VConf310/lib/python3.10/site-packages/flask/app.py", line 1820, in full_dispatch_request
    rv = self.dispatch_request()
  File "/home/c/Code/VConf310/lib/python3.10/site-packages/flask/app.py", line 1796, in dispatch_request
    return self.ensure_sync(self.view_functions[rule.endpoint])(**view_args)
  File "/home/c/Code/github/tFlask-Image-Gallery/routes.py", line 42, in download_file
    if Path(app.instance_path, 'qrs', filename).exists():
UnboundLocalError: local variable 'filename' referenced before assignment
INFO:werkzeug:192.168.5.2 - - [25/Aug/2022 12:29:08] "[35m[1mGET /cdn/0.5113559359673016 HTTP/1.1[0m" 500 -
ERROR:Zortom:Exception on /cdn/0.5272656506310458 [GET]
Traceback (most recent call last):
  File "/home/c/Code/VConf310/lib/python3.10/site-packages/flask/app.py", line 2525, in wsgi_app
    response = self.full_dispatch_request()
  File "/home/c/Code/VConf310/lib/python3.10/site-packages/flask/app.py", line 1822, in full_dispatch_request
    rv = self.handle_user_exception(e)
  File "/home/c/Code/VConf310/lib/python3.10/site-packages/flask/app.py", line 1820, in full_dispatch_request
    rv = self.dispatch_request()
  File "/home/c/Code/VConf310/lib/python3.10/site-packages/flask/app.py", line 1796, in dispatch_request
    return self.ensure_sync(self.view_functions[rule.endpoint])(**view_args)
  File "/home/c/Code/github/tFlask-Image-Gallery/routes.py", line 42, in download_file
    if Path(app.instance_path, 'qrs', filename).exists():
UnboundLocalError: local variable 'filename' referenced before assignment
INFO:werkzeug:192.168.5.2 - - [25/Aug/2022 12:29:08] "[35m[1mGET /cdn/0.4564846952232354 HTTP/1.1[0m" 500 -
ERROR:Zortom:Exception on /cdn/0.6258321076250696 [GET]
Traceback (most recent call last):
  File "/home/c/Code/VConf310/lib/python3.10/site-packages/flask/app.py", line 2525, in wsgi_app
    response = self.full_dispatch_request()
  File "/home/c/Code/VConf310/lib/python3.10/site-packages/flask/app.py", line 1822, in full_dispatch_request
    rv = self.handle_user_exception(e)
  File "/home/c/Code/VConf310/lib/python3.10/site-packages/flask/app.py", line 1820, in full_dispatch_request
    rv = self.dispatch_request()
  File "/home/c/Code/VConf310/lib/python3.10/site-packages/flask/app.py", line 1796, in dispatch_request
    return self.ensure_sync(self.view_functions[rule.endpoint])(**view_args)
  File "/home/c/Code/github/tFlask-Image-Gallery/routes.py", line 42, in download_file
    if Path(app.instance_path, 'qrs', filename).exists():
UnboundLocalError: local variable 'filename' referenced before assignment
INFO:werkzeug:192.168.5.2 - - [25/Aug/2022 12:29:08] "[35m[1mGET /cdn/0.6258321076250696 HTTP/1.1[0m" 500 -
INFO:werkzeug:192.168.5.2 - - [25/Aug/2022 12:29:08] "[35m[1mGET /cdn/0.5272656506310458 HTTP/1.1[0m" 500 -
ERROR:Zortom:Exception on /cdn/0.6829552997387811 [GET]
Traceback (most recent call last):
  File "/home/c/Code/VConf310/lib/python3.10/site-packages/flask/app.py", line 2525, in wsgi_app
    response = self.full_dispatch_request()
  File "/home/c/Code/VConf310/lib/python3.10/site-packages/flask/app.py", line 1822, in full_dispatch_request
    rv = self.handle_user_exception(e)
  File "/home/c/Code/VConf310/lib/python3.10/site-packages/flask/app.py", line 1820, in full_dispatch_request
    rv = self.dispatch_request()
  File "/home/c/Code/VConf310/lib/python3.10/site-packages/flask/app.py", line 1796, in dispatch_request
    return self.ensure_sync(self.view_functions[rule.endpoint])(**view_args)
  File "/home/c/Code/github/tFlask-Image-Gallery/routes.py", line 42, in download_file
    if Path(app.instance_path, 'qrs', filename).exists():
UnboundLocalError: local variable 'filename' referenced before assignment
INFO:werkzeug:192.168.5.2 - - [25/Aug/2022 12:29:08] "[35m[1mGET /cdn/0.6829552997387811 HTTP/1.1[0m" 500 -
ERROR:Zortom:Exception on /cdn/0.8008783271080552 [GET]
Traceback (most recent call last):
  File "/home/c/Code/VConf310/lib/python3.10/site-packages/flask/app.py", line 2525, in wsgi_app
    response = self.full_dispatch_request()
  File "/home/c/Code/VConf310/lib/python3.10/site-packages/flask/app.py", line 1822, in full_dispatch_request
    rv = self.handle_user_exception(e)
  File "/home/c/Code/VConf310/lib/python3.10/site-packages/flask/app.py", line 1820, in full_dispatch_request
    rv = self.dispatch_request()
  File "/home/c/Code/VConf310/lib/python3.10/site-packages/flask/app.py", line 1796, in dispatch_request
    return self.ensure_sync(self.view_functions[rule.endpoint])(**view_args)
  File "/home/c/Code/github/tFlask-Image-Gallery/routes.py", line 42, in download_file
    if Path(app.instance_path, 'qrs', filename).exists():
UnboundLocalError: local variable 'filename' referenced before assignment
INFO:werkzeug:192.168.5.2 - - [25/Aug/2022 12:29:08] "[35m[1mGET /cdn/0.8008783271080552 HTTP/1.1[0m" 500 -
ERROR:Zortom:Exception on /cdn/0.9930338761531676 [GET]
Traceback (most recent call last):
  File "/home/c/Code/VConf310/lib/python3.10/site-packages/flask/app.py", line 2525, in wsgi_app
    response = self.full_dispatch_request()
  File "/home/c/Code/VConf310/lib/python3.10/site-packages/flask/app.py", line 1822, in full_dispatch_request
    rv = self.handle_user_exception(e)
  File "/home/c/Code/VConf310/lib/python3.10/site-packages/flask/app.py", line 1820, in full_dispatch_request
    rv = self.dispatch_request()
  File "/home/c/Code/VConf310/lib/python3.10/site-packages/flask/app.py", line 1796, in dispatch_request
    return self.ensure_sync(self.view_functions[rule.endpoint])(**view_args)
  File "/home/c/Code/github/tFlask-Image-Gallery/routes.py", line 42, in download_file
    if Path(app.instance_path, 'qrs', filename).exists():
UnboundLocalError: local variable 'filename' referenced before assignment
ERROR:Zortom:Exception on /cdn/0.7929434148298635 [GET]
Traceback (most recent call last):
  File "/home/c/Code/VConf310/lib/python3.10/site-packages/flask/app.py", line 2525, in wsgi_app
    response = self.full_dispatch_request()
  File "/home/c/Code/VConf310/lib/python3.10/site-packages/flask/app.py", line 1822, in full_dispatch_request
    rv = self.handle_user_exception(e)
  File "/home/c/Code/VConf310/lib/python3.10/site-packages/flask/app.py", line 1820, in full_dispatch_request
    rv = self.dispatch_request()
  File "/home/c/Code/VConf310/lib/python3.10/site-packages/flask/app.py", line 1796, in dispatch_request
    return self.ensure_sync(self.view_functions[rule.endpoint])(**view_args)
  File "/home/c/Code/github/tFlask-Image-Gallery/routes.py", line 42, in download_file
    if Path(app.instance_path, 'qrs', filename).exists():
UnboundLocalError: local variable 'filename' referenced before assignment
INFO:werkzeug:192.168.5.2 - - [25/Aug/2022 12:29:08] "[35m[1mGET /cdn/0.7929434148298635 HTTP/1.1[0m" 500 -
INFO:werkzeug:192.168.5.2 - - [25/Aug/2022 12:29:08] "[35m[1mGET /cdn/0.9930338761531676 HTTP/1.1[0m" 500 -
ERROR:Zortom:Exception on /cdn/0.7213341320765407 [GET]
Traceback (most recent call last):
  File "/home/c/Code/VConf310/lib/python3.10/site-packages/flask/app.py", line 2525, in wsgi_app
    response = self.full_dispatch_request()
  File "/home/c/Code/VConf310/lib/python3.10/site-packages/flask/app.py", line 1822, in full_dispatch_request
    rv = self.handle_user_exception(e)
  File "/home/c/Code/VConf310/lib/python3.10/site-packages/flask/app.py", line 1820, in full_dispatch_request
    rv = self.dispatch_request()
  File "/home/c/Code/VConf310/lib/python3.10/site-packages/flask/app.py", line 1796, in dispatch_request
    return self.ensure_sync(self.view_functions[rule.endpoint])(**view_args)
  File "/home/c/Code/github/tFlask-Image-Gallery/routes.py", line 42, in download_file
    if Path(app.instance_path, 'qrs', filename).exists():
UnboundLocalError: local variable 'filename' referenced before assignment
INFO:werkzeug:192.168.5.2 - - [25/Aug/2022 12:29:08] "[35m[1mGET /cdn/0.7213341320765407 HTTP/1.1[0m" 500 -
ERROR:Zortom:Exception on /cdn/0.7882520702931711 [GET]
Traceback (most recent call last):
  File "/home/c/Code/VConf310/lib/python3.10/site-packages/flask/app.py", line 2525, in wsgi_app
    response = self.full_dispatch_request()
  File "/home/c/Code/VConf310/lib/python3.10/site-packages/flask/app.py", line 1822, in full_dispatch_request
    rv = self.handle_user_exception(e)
  File "/home/c/Code/VConf310/lib/python3.10/site-packages/flask/app.py", line 1820, in full_dispatch_request
    rv = self.dispatch_request()
  File "/home/c/Code/VConf310/lib/python3.10/site-packages/flask/app.py", line 1796, in dispatch_request
    return self.ensure_sync(self.view_functions[rule.endpoint])(**view_args)
  File "/home/c/Code/github/tFlask-Image-Gallery/routes.py", line 42, in download_file
    if Path(app.instance_path, 'qrs', filename).exists():
UnboundLocalError: local variable 'filename' referenced before assignment
INFO:werkzeug:192.168.5.2 - - [25/Aug/2022 12:29:08] "[35m[1mGET /cdn/0.7882520702931711 HTTP/1.1[0m" 500 -
INFO:werkzeug:192.168.5.2 - - [25/Aug/2022 12:29:08] "[33mGET /favicon.ico HTTP/1.1[0m" 404 -
